<?xml version="1.0" encoding="utf-8"?>

<robot
  name="autonomous_robot_3">
  
   <material name="red">
    <color rgba="1 0 0 1"/> 
  </material>
  <material name="green">
    <color rgba="0 1 0 1"/> 
  </material>
  <material name="blue">
    <color rgba="0 0 1 1"/> 
  </material>
  <material name="semi_transparent_yellow">
    <color rgba="1 1 0 0.5"/> 
  </material>
  
  <link
    name="base_link">
    <inertial>
      <origin
        xyz="-0.0626 0.00015231 0.15761"
        rpy="0 0 0" />
      <mass
        value="0.61968" />
      <inertia
        ixx="0.0079493"
        ixy="1.3324E-06"
        ixz="-3.4315E-06"
        iyy="0.0082099"
        iyz="2.6324E-08"
        izz="0.00088916" />
    </inertial>
    <visual>
      <origin
        xyz="0 0 0"
        rpy="0 0 0" />
      <geometry>
        <mesh
          filename="package://autonomous_robot_3/meshes/base_link.STL" />
      </geometry>
      <material name="blue">
        
      </material>
    </visual>
    <collision>
      <origin
        xyz="0 0 0"
        rpy="0 0 0" />
      <geometry>
        <mesh
          filename="package://autonomous_robot_3/meshes/base_link.STL" />
      </geometry>
    </collision>
  </link>
  <link
    name="linkrightfront">
    <inertial>
      <origin
        xyz="1.52E-08 0.0098402 1.296E-08"
        rpy="0 0 0" />
      <mass
        value="0.045564" />
      <inertia
        ixx="1.7813E-05"
        ixy="3.195E-12"
        ixz="9.3846E-12"
        iyy="3.2421E-05"
        iyz="2.7552E-12"
        izz="1.7813E-05" />
    </inertial>
    <visual>
      <origin
        xyz="0 0 0"
        rpy="0 0 0" />
      <geometry>
        <mesh
          filename="package://autonomous_robot_3/meshes/linkrightfront.STL" />
      </geometry>
      <material
        name="green">
        
      </material>
    </visual>
    <collision>
      <origin
        xyz="0 0 0"
        rpy="0 0 0" />
      <geometry>
        <mesh
          filename="package://autonomous_robot_3/meshes/linkrightfront.STL" />
      </geometry>
      <gazebo>
        <material>Gazebo/Black</material>
        <surface>
          <friction>
            <ode>
              <mu>3.0</mu>
              <mu2>3.0</mu2>
            </ode>
          </friction>
        </surface>
      </gazebo>
    </collision>
  </link>
  <joint
    name="jointrightfront"
    type="continuous">
    <origin
      xyz="0.082613 -0.093717 -0.0125"
      rpy="0 0 0" />
    <parent
      link="base_link" />
    <child
      link="linkrightfront" />
    <axis
      xyz="0 1 0" />
    <limit
      effort="1"
      velocity="1" />
  </joint>
  <link
    name="linkleftfront">
    <inertial>
      <origin
        xyz="-1.5699E-08 -0.0098402 -1.2351E-08"
        rpy="0 0 0" />
      <mass
        value="0.045564" />
      <inertia
        ixx="1.7813E-05"
        ixy="3.3302E-12"
        ixz="1.5447E-11"
        iyy="3.2421E-05"
        iyz="2.5901E-12"
        izz="1.7813E-05" />
    </inertial>
    <visual>
      <origin
        xyz="0 0 0"
        rpy="0 0 0" />
      <geometry>
        <mesh
          filename="package://autonomous_robot_3/meshes/linkleftfront.STL" />
      </geometry>
      <material
        name="green">
        
      </material>
    </visual>
    <collision>
      <origin
        xyz="0 0 0"
        rpy="0 0 0" />
      <geometry>
        <mesh
          filename="package://autonomous_robot_3/meshes/linkleftfront.STL" />
      </geometry>
      <gazebo>
        <material>Gazebo/Black</material>
        <surface>
          <friction>
            <ode>
              <mu>3.0</mu>
              <mu2>3.0</mu2>
            </ode>
          </friction>
        </surface>
      </gazebo>
    </collision>
  </link>
  <joint
    name="jointleftfront"
    type="continuous">
    <origin
      xyz="0.0826127763161896 0.0940910896506304 -0.0125"
      rpy="0 0 0" />
    <parent
      link="base_link" />
    <child
      link="linkleftfront" />
    <axis
      xyz="0 -1 0" />
    <limit
      effort="1"
      velocity="1" />
  </joint>
  <link
    name="linkleftback">
    <inertial>
      <origin
        xyz="-1.9697E-08 -0.0098402 3.3224E-09"
        rpy="0 0 0" />
      <mass
        value="0.045564" />
      <inertia
        ixx="1.7813E-05"
        ixy="4.1561E-12"
        ixz="1.1056E-11"
        iyy="3.2421E-05"
        iyz="-7.249E-13"
        izz="1.7813E-05" />
    </inertial>
    <visual>
      <origin
        xyz="0 0 0"
        rpy="0 0 0" />
      <geometry>
        <mesh
          filename="package://autonomous_robot_3/meshes/linkleftback.STL" />
      </geometry>
      <material
        name="green">
        
      </material>
    </visual>
    <collision>
      <origin
        xyz="0 0 0"
        rpy="0 0 0" />
      <geometry>
        <mesh
          filename="package://autonomous_robot_3/meshes/linkleftback.STL" />
      </geometry>
      <gazebo>
        <material>Gazebo/Black</material>
        <surface>
          <friction>
            <ode>
              <mu>3.0</mu>
              <mu2>3.0</mu2>
            </ode>
          </friction>
        </surface>
      </gazebo>
    </collision>
  </link>
  <joint
    name="jointleftback"
    type="continuous">
    <origin
      xyz="-0.0819456955624622 0.0940910896506303 -0.0125"
      rpy="0 0 0" />
    <parent
      link="base_link" />
    <child
      link="linkleftback" />
    <axis
      xyz="0 -1 0" />
    <limit
      effort="1"
      velocity="1" />
  </joint>
  <link
    name="linkrightback">
    <inertial>
      <origin
        xyz="1.6867E-08 0.0098402 -1.0701E-08"
        rpy="0 0 0" />
      <mass
        value="0.045564" />
      <inertia
        ixx="1.7813E-05"
        ixy="3.575E-12"
        ixz="-1.7667E-11"
        iyy="3.2421E-05"
        iyz="-2.2402E-12"
        izz="1.7813E-05" />
    </inertial>
    <visual>
      <origin
        xyz="0 0 0"
        rpy="0 0 0" />
      <geometry>
        <mesh
          filename="package://autonomous_robot_3/meshes/linkrightback.STL" />
      </geometry>
      <material
        name="green">
        
      </material>
    </visual>
    <collision>
      <origin
        xyz="0 0 0"
        rpy="0 0 0" />
      <geometry>
        <mesh
          filename="package://autonomous_robot_3/meshes/linkrightback.STL" />
      </geometry>
      <gazebo>
        <material>Gazebo/Black</material>
        <surface>
          <friction>
            <ode>
              <mu>3.0</mu>
              <mu2>3.0</mu2>
            </ode>
          </friction>
        </surface>
      </gazebo>
    </collision>
  </link>
  <joint
    name="jointrightback"
    type="continuous">
    <origin
      xyz="-0.0819456955624622 -0.0937168736180515 -0.0125000000000001"
      rpy="0 0 0" />
    <parent
      link="base_link" />
    <child
      link="linkrightback" />
    <axis
      xyz="0 1 0" />
    <limit
      effort="1"
      velocity="1" />
  </joint>
  <link
    name="link_tray">
    <inertial>
      <origin
        xyz="-0.01397 -4.2432E-07 -0.00011074"
        rpy="0 0 0" />
      <mass
        value="0.059654" />
      <inertia
        ixx="9.9826E-05"
        ixy="7.4413E-10"
        ixz="1.3325E-06"
        iyy="0.00018415"
        iyz="-3.9583E-11"
        izz="0.00028361" />
    </inertial>
    <visual>
      <origin
        xyz="0 0 0"
        rpy="0 0 0" />
      <geometry>
        <mesh
          filename="package://autonomous_robot_3/meshes/link_tray.STL" />
      </geometry>
      <material
        name="">
        <color
          rgba="0.25098 0.25098 0.25098 1" />
      </material>
    </visual>
    <collision>
      <origin
        xyz="0 0 0"
        rpy="0 0 0" />
      <geometry>
        <mesh
          filename="package://autonomous_robot_3/meshes/link_tray.STL" />
      </geometry>
    </collision>
  </link>
  <joint
    name="joint_tray"
    type="prismatic">
    <origin
      xyz="0.0051786 -0.0035764 0.007"
      rpy="0 0 0" />
    <parent
      link="base_link" />
    <child
      link="link_tray" />
    <axis
      xyz="0 0 1" />
    <limit
      lower="0"
      upper="0.4"
      effort="1"
      velocity="1" />
  </joint>
  
  <!--<gazebo>
    <plugin name="skid_steer_drive_controller" filename="libgazebo_ros_skid_steer_drive.so">
      <updateRate>100.0</updateRate>
      <robotNamespace>/</robotNamespace>
      <leftFrontJoint>jointleftfront</leftFrontJoint>
      <rightFrontJoint>jointrightfront</rightFrontJoint>
      <leftRearJoint>jointleftback</leftRearJoint>
      <rightRearJoint>jointrightback</rightRearJoint>
      <wheelSeparation>1.5</wheelSeparation>
      <wheelDiameter>0.25</wheelDiameter>
      <robotBaseFrame>base_link</robotBaseFrame>
      <torque>15</torque>
      <commandTopic>cmd_vel</commandTopic>
      <commandTopic>cmd_vel</commandTopic>
      <odometryTopic>odom</odometryTopic>
      <odometryFrame>odom</odometryFrame>
      <odometryRate>20.0</odometryRate>
      <covariance_x>0.0001</covariance_x>
      <covariance_y>0.0001</covariance_y>
      <covariance_yaw>0.01</covariance_yaw>
    </plugin>
  </gazebo>-->


  <gazebo>
    <plugin name="omni_steering" filename="libgazebo_ros_planar_move.so">
      <commandTopic>cmd_vel</commandTopic>
      <odometryTopic>odom</odometryTopic>
      <odometryFrame>odom</odometryFrame>
      <odometryRate>20.0</odometryRate>	
      <robotBaseFrame>base_link</robotBaseFrame>
    </plugin>
    <gazebo>
  <plugin name="gazebo_ros_control" filename="libgazebo_ros_control.so">
    <robotNamespace>/robot</robotNamespace>
  </plugin>
</gazebo>

  </gazebo>
  
    
  <!--<gazebo>
  <plugin name="differential_drive_controller_1" filename="libgazebo_ros_diff_drive.so">

    <updateRate>100</updateRate>
    <leftFrontJoint>jointleftfront</leftFrontJoint>
      <rightFrontJoint>jointrightfront</rightFrontJoint>
    
      <wheelSeparation>1.5</wheelSeparation>
      <wheelDiameter>0.25</wheelDiameter>
    <wheelTorque>20</wheelTorque>
    <commandTopic>cmd_vel</commandTopic>
    <odometryTopic>odom</odometryTopic>
    <odometryFrame>odom</odometryFrame>
    <robotBaseFrame>base_link</robotBaseFrame>
    <odometrySource>1</odometrySource>
    <publishWheelTF>false</publishWheelTF>
    <publishOdom>true</publishOdom>
    <publishWheelJointState>true</publishWheelJointState>
    <legacyMode>false</legacyMode>
  </plugin>
</gazebo>

  <gazebo>
  <plugin name="differential_drive_controller_2" filename="libgazebo_ros_diff_drive.so">

    <updateRate>100</updateRate>
  
      <leftRearJoint>jointleftback</leftRearJoint>
      <rightRearJoint>jointrightback</rightRearJoint>
      <wheelSeparation>1.5</wheelSeparation>
      <wheelDiameter>0.25</wheelDiameter>
    <wheelTorque>20</wheelTorque>
    <commandTopic>cmd_vel</commandTopic>
    <odometryTopic>odom</odometryTopic>
    <odometryFrame>odom</odometryFrame>
    <robotBaseFrame>base_link</robotBaseFrame>
    <odometrySource>1</odometrySource>
    <publishWheelTF>false</publishWheelTF>
    <publishOdom>true</publishOdom>
    <publishWheelJointState>true</publishWheelJointState>
    <legacyMode>false</legacyMode>
  </plugin>
</gazebo>-->

 
  <joint name="camera_joint" type="fixed">
    <axis xyz="0 1 0" />
    <origin xyz="0.095 0.02 0.01" rpy="0 0 0"/>
    <parent link="base_link"/>
    <child link="camera_link"/>
  </joint>

  <!-- Camera -->
  <link name="camera_link">
    <collision>
      <origin xyz="0 0 0" rpy="0 0 0"/>
      <geometry>
    <box size="0.01 0.01 0.02"/>
      </geometry>
    </collision>

    <visual>
      <origin xyz="0 0 0" rpy="0 0 0"/>
      <geometry>
    <box size="0.01 0.01 0.02"/>
      </geometry>
      <material name="red">
        <color rgba="1.0 0.0 0.0 1.0"/>
      </material>
    </visual>

    <inertial>
      <mass value="1e-5" />
      <origin xyz="0 0 0" rpy="0 0 0"/>
      <inertia ixx="1e-6" ixy="0" ixz="0" iyy="1e-6" iyz="0" izz="1e-6" />
    </inertial>
  </link>
  <!-- camera -->
  <gazebo reference="camera_link">
    <sensor type="camera" name="camera1">
      <update_rate>30.0</update_rate>
      <camera name="head">
        <horizontal_fov>1.3962634</horizontal_fov>
        <image>
          <width>800</width>
          <height>800</height>
          <format>R8G8B8</format>
        </image>
        <clip>
          <near>0.02</near>
          <far>300</far>
        </clip>
        <noise>
          <type>gaussian</type>
          <!-- Noise is sampled independently per pixel on each frame.
               That pixel's noise value is added to each of its color
               channels, which at that point lie in the range [0,1]. -->
          <mean>0.0</mean>
          <stddev>0.007</stddev>
        </noise>
      </camera>
      <plugin name="camera_controller" filename="libgazebo_ros_camera.so">
        <alwaysOn>true</alwaysOn>
        <updateRate>0.0</updateRate>
        <cameraName>rrbot/camera1</cameraName>
        <imageTopicName>image_raw</imageTopicName>
        <cameraInfoTopicName>camera_info</cameraInfoTopicName>
        <frameName>camera_link</frameName>
        <hackBaseline>0.07</hackBaseline>
        <distortionK1>0.0</distortionK1>
        <distortionK2>0.0</distortionK2>
        <distortionK3>0.0</distortionK3>
        <distortionT1>0.0</distortionT1>
        <distortionT2>0.0</distortionT2>
      </plugin>
    </sensor>
  </gazebo>
  
   <joint name="hokuyo_joint" type="fixed">
    <axis xyz="0 1 0" />
    <origin xyz="0.095 -0.02 0.01" rpy="0 0 0"/>
    <parent link="base_link"/>
    <child link="hokuyo_link"/>
  </joint>

  <!-- Hokuyo Laser -->
  <link name="hokuyo_link">
    <collision>
      <origin xyz="0 0 0" rpy="0 0 0"/>
      <geometry>
    <box size="0.01 0.01 0.01"/>
      </geometry>
    </collision>

    <visual>
      <origin xyz="0 0 0" rpy="0 0 0"/>
      <geometry>
        <box size="0.01 0.01 0.01"/>
      </geometry>
      <material name="red">
        <color rgba="1.0 0.0 0.0 1.0"/>
      </material>
    </visual>

    <inertial>
      <mass value="1e-5" />
      <origin xyz="0 0 0" rpy="0 0 0"/>
      <inertia ixx="1e-6" ixy="0" ixz="0" iyy="1e-6" iyz="0" izz="1e-6" />
    </inertial>
  </link>
  <!-- hokuyo -->
  <gazebo reference="hokuyo_link">
    <sensor type="ray" name="head_hokuyo_sensor">
      <pose>0 0 0 0 0 0</pose>
      <visualize>true</visualize>
      <update_rate>20</update_rate>
      <ray>
        <scan>
          <horizontal>
            <samples>720</samples>
            <resolution>1</resolution>
            <min_angle>-1.57</min_angle>
            <max_angle>1.57</max_angle>
          </horizontal>
        </scan>
        <range>
          <min>0.4</min>
          <max>7.0</max>
          <resolution>0.01</resolution>
        </range>
        <noise>
          <type>gaussian</type>
          <!-- Noise parameters based on published spec for Hokuyo laser
               achieving "+-30mm" accuracy at range < 10m.  A mean of 0.0m and
               stddev of 0.01m will put 99.7% of samples within 0.03m of the true
               reading. -->
          <mean>0.0</mean>
          <stddev>0.01</stddev>
        </noise>
      </ray>
      <plugin name="gazebo_ros_head_hokuyo_controller" filename="libgazebo_ros_laser.so">
        <topicName>/scan</topicName>
        <frameName>hokuyo_link</frameName>
      </plugin>
    </sensor>
  </gazebo>
</robot>
